Workbook

Sheet Dashboard
B2: Painel de Pessoas | Y2: FECHAMENTO DA FOLHA
B3: RH · headcount, movimentação, turnover, perfil e remuneração | Y3: =Calc!B7
B5: DEPTO | D5: Todos | G5: UNIDADE | I5: Todas | L5: ANO | N5: 2026 | Q5: ◀ Ano vale para admissões, desligamentos e turnover. Headcount é a foto do fechamento.
B7: HEADCOUNT ATIVO | G7: ADMISSÕES | L7: DESLIGAMENTOS | Q7: TURNOVER | V7: SALÁRIO MÉDIO | AA7: MULHERES
B8: =Calc!B13 | G8: =Calc!B14 | L8: =Calc!B16 | Q8: =Calc!B18 | V8: =Calc!B19 | AA8: =Calc!B21
B10: =Calc!B23 | G10: =Calc!B24 | L10: =Calc!B25 | Q10: ="(adm. + desl.) ÷ 2 ÷ ativos" | V10: =Calc!B20 | AA10: =Calc!B22
B12: Pessoas por departamento | M12: Admissões × desligamentos por mês
B13: ativos no fechamento | M13: ano escolhido · quando a barra laranja passa a azul, o time está encolhendo
B29: Pirâmide etária | P29: Por que as pessoas saem | Y29: Gênero
B30: ativos por faixa de idade · mulheres à direita, homens à esquerda | P30: desligamentos no ano por motivo | Y30: ativos
B46: Quadro por departamento
B47: barra = salário médio · cor da avaliação: vermelho (baixa) → verde (alta)
B48: DEPARTAMENTO | G48: ATIVOS | I48: % MULHERES | L48: SALÁRIO MÉDIO | R48: TEMPO DE CASA | U48: AVALIAÇÃO | X48: ADMISSÕES | AA48: DESLIGAMENTOS
B49: =Calc!A74 | G49: =Calc!B74 | I49: =Calc!C74 | L49: =Calc!D74 | R49: =Calc!E74 | U49: =Calc!F74 | X49: =Calc!G74 | AA49: =Calc!H74
B50: =Calc!A75 | G50: =Calc!B75 | I50: =Calc!C75 | L50: =Calc!D75 | R50: =Calc!E75 | U50: =Calc!F75 | X50: =Calc!G75 | AA50: =Calc!H75
B51: =Calc!A76 | G51: =Calc!B76 | I51: =Calc!C76 | L51: =Calc!D76 | R51: =Calc!E76 | U51: =Calc!F76 | X51: =Calc!G76 | AA51: =Calc!H76
B52: =Calc!A77 | G52: =Calc!B77 | I52: =Calc!C77 | L52: =Calc!D77 | R52: =Calc!E77 | U52: =Calc!F77 | X52: =Calc!G77 | AA52: =Calc!H77
B53: =Calc!A78 | G53: =Calc!B78 | I53: =Calc!C78 | L53: =Calc!D78 | R53: =Calc!E78 | U53: =Calc!F78 | X53: =Calc!G78 | AA53: =Calc!H78
B54: =Calc!A79 | G54: =Calc!B79 | I54: =Calc!C79 | L54: =Calc!D79 | R54: =Calc!E79 | U54: =Calc!F79 | X54: =Calc!G79 | AA54: =Calc!H79
B55: =Calc!A80 | G55: =Calc!B80 | I55: =Calc!C80 | L55: =Calc!D80 | R55: =Calc!E80 | U55: =Calc!F80 | X55: =Calc!G80 | AA55: =Calc!H80
B59: Dados fictícios para estudo. Turnover = ((admissões + desligamentos) ÷ 2) ÷ headcount ativo, no período. A pirâmide etária usa um truque: os homens entram com sinal negativo e o formato de número esconde o sinal.

Sheet Passo a passo
B2: Passo a passo · Painel de Pessoas
B3: Siga as etapas na ordem. Cada linha diz onde clicar, o que fazer, a fórmula e o porquê.
B5: ETAPA 1 · Base de funcionários
B6: Uma linha por pessoa. Datas de admissão e desligamento são a matéria-prima de quase todos os indicadores de RH.
B7: Passo | C7: Onde | D7: O que fazer | E7: Fórmula / recurso | F7: Por que assim
B8: 1 | C8: Funcionarios | D8: Transforme em Tabela (tbFuncionarios). | E8: Ctrl + Alt + T | F8: Contratou alguém? Nova linha, painel atualizado.
B9: 2 | C9: Funcionarios › Idade | D9: Idade na data de referência (ou no desligamento). | E9: =DATADIF(D2;SE(K2="";Calc!$B$7;K2);"a") | F9: DATADIF com "a" conta anos completos. Ela não aparece no assistente, mas funciona.
B10: 3 | C10: Funcionarios › Faixa etária | D10: Agrupe idades em faixas. | E10: =PROC(E2;{0;25;35;45;55};{"18-24";"25-34";"35-44";"45-54";"55+"}) | F10: PROC aproximado acha a faixa certa: 31 cai em 25-34.
B11: 4 | C11: Funcionarios › Status | D11: Ativo se não tem data de desligamento. | E11: =SE(K2="";"Ativo";"Desligado") | F11: Headcount = contar 'Ativo'.
B12: 5 | C12: Funcionarios › Tempo de casa | D12: Anos entre admissão e hoje (ou desligamento). | E12: =ARRED((SE(K2="";ref;K2)-J2)/365,25;1) | F12: Datas são números: subtrair dá dias; ÷365,25 dá anos.
B13: 6 | C13: Funcionarios › Liderança | D13: Marca quem é Coordenação, Gerência ou Diretoria. | E13: =SE(OU(H2="Coordenação";H2="Gerência";H2="Diretoria");"Sim";"Não") | F13: Permite medir diversidade na liderança.
B15: ETAPA 2 · Os KPIs de RH
B16: Passo | C16: Onde | D16: O que fazer | E16: Fórmula / recurso | F16: Por que assim
B17: 7 | C17: Calc › B13 | D17: Headcount ativo com filtros. | E17: =CONT.SES(Status;"Ativo";Depto;critério;Unidade;critério) | F17: Foto do fechamento: quantas pessoas estão na casa hoje.
B18: 8 | C18: Calc › B14 e B16 | D18: Admissões e desligamentos no ano. | E18: =CONT.SES(Admissão;">="&início;Admissão;"<="&fim;…) | F18: Movimento é sempre num período: precisa de data inicial e final.
B19: 9 | C19: Calc › B18 | D19: Turnover. | E19: =SEERRO(((B14+B16)/2)/B13;0) | F19: Fórmula de mercado: média entre entradas e saídas sobre o quadro. Acima de ~15% ao ano acende alerta.
B20: 10 | C20: Calc › B19 e B20 | D20: Salário médio e folha. | E20: =MÉDIASES(Salário;Status;"Ativo";…) · =SOMASES(…) | F20: Média mostra o 'típico'; folha mostra o custo total.
B21: 11 | C21: Calc › B21 e B22 | D21: Diversidade: % mulheres e % mulheres na liderança. | E21: =CONT.SES(…;Gênero;"F";Liderança;"Sim")/CONT.SES(…;Liderança;"Sim") | F21: Os dois juntos contam a história: equilíbrio geral × no topo.
B23: ETAPA 3 · Pirâmide etária (truque de especialista)
B24: Não existe 'gráfico de pirâmide' no Excel. Ele é um gráfico de barras com um detalhe esperto.
B25: Passo | C25: Onde | D25: O que fazer | E25: Fórmula / recurso | F25: Por que assim
B26: 12 | C26: Calc › seção 5 | D26: Conte mulheres por faixa (positivo) e homens por faixa com sinal NEGATIVO. | E26: =-CONT.SES(…;Gênero;"M") | F26: Valor negativo faz a barra crescer para a esquerda.
B27: 13 | C27: Inserir | D27: Gráfico de Barras Agrupadas com as duas séries. | E27: Inserir › Barras › Barra Agrupada | F27: Uma série para cada lado.
B28: 14 | C28: Formatar Série | D28: Sobreposição 100% e largura do espaçamento 25%. | E28: Formatar Série › Sobreposição: 100% | F28: As duas barras ficam na mesma linha, uma de cada lado do zero.
B29: 15 | C29: Formatar Eixo e rótulos | D29: Formato de número que esconde o sinal de menos. | E29: Formato: #.##0;#.##0 | F29: A segunda parte do formato (negativos) é escrita sem o '-'. O gráfico mostra 12, não −12.
B30: 16 | C30: Eixo vertical | D30: Rótulos do eixo em 'Baixo'. | E30: Formatar Eixo › Rótulos › Posição: Baixo | F30: Tira os nomes das faixas do meio da pirâmide.
B32: ETAPA 4 · Demais visuais
B33: Passo | C33: Onde | D33: O que fazer | E33: Fórmula / recurso | F33: Por que assim
B34: 17 | C34: Pessoas por departamento | D34: Barras horizontais da tabela ordenada (MAIOR + ÍNDICE/CORRESP). | E34: Formatar Eixo › Categorias em ordem inversa | F34: Ranking lido de cima para baixo.
B35: 18 | C35: Admissões × desligamentos | D35: Colunas agrupadas: azul = entra, laranja = sai. | E35: Inserir › Coluna Agrupada | F35: Mês a mês dá para ver se o time cresce ou encolhe.
B36: 19 | C36: Gênero | D36: Rosca com 2 fatias e rótulos em %. | E36: Inserir › Rosca | F36: Rosca é ótima para 2 a 4 partes de um todo.
B37: 20 | C37: Quadro por departamento | D37: Barras de dados no salário e escala de cores na avaliação. | E37: Formatação Condicional › Escalas de Cor › Mais Regras (mín 3,2 · ponto médio 3,8 · máx 4,4) | F37: Limites fixos: a cor tem o mesmo significado em qualquer filtro.
B39: ETAPA 5 · Desafios para virar especialista
B40: Passo | C40: Onde | D40: O que fazer | E40: Fórmula / recurso | F40: Por que assim
B41: 21 | C41: Desafio 1 | D41: Crie o KPI 'Absenteísmo' com uma nova tabela de faltas. | E41: Nova Tabela + SOMASES | F41: Painel de RH real cruza várias bases.
B42: 22 | C42: Desafio 2 | D42: Adicione 'Tempo médio até o desligamento' de quem saiu no ano. | E42: MÉDIASES(Tempo de casa;Status;"Desligado";…) | F42: Mostra se as pessoas saem cedo (problema de integração) ou tarde.
B43: 23 | C43: Desafio 3 | D43: Faça uma matriz Nível × Gênero com salário médio e destaque diferenças acima de 5%. | E43: MÉDIASES com dois critérios + formatação condicional | F43: Equidade salarial é tema quente em qualquer empresa.

Sheet Calc
A1: 1 · FILTROS E DATAS
A3: Departamento escolhido | B3: =Dashboard!$D$5
A4: Unidade escolhida | B4: =Dashboard!$I$5
A5: Ano dos movimentos | B5: =Dashboard!$N$5
A6: Critério depto · unidade | B6: =IF($B$3="Todos","*",$B$3) | C6: =IF($B$4="Todas","*",$B$4)
A7: Data de referência (fechamento) | B7: 46295 | C7: premissa: data do último fechamento da folha
A8: Início do ano | B8: =DATE($B$5,1,1)
A9: Fim efetivo do ano | B9: =MIN(DATE($B$5,12,31),$B$7)
A10: Mesmo período ano anterior (fim) | B10: =EDATE($B$9,-12)
A12: 2 · KPIs
A13: Headcount ativo | B13: =COUNTIFS(Funcionarios!$O$2:$O$176,"Ativo",Funcionarios!$G$2:$G$176,$B$6,Funcionarios!$M$2:$M$176,$C$6)
A14: Admissões no ano | B14: =COUNTIFS(Funcionarios!$J$2:$J$176,">="&$B$8,Funcionarios!$J$2:$J$176,"<="&$B$9,Funcionarios!$G$2:$G$176,$B$6,Funcionarios!$M$2:$M$176,$C$6)
A15: Admissões mesmo período ano anterior | B15: =COUNTIFS(Funcionarios!$J$2:$J$176,">="&EDATE($B$8,-12),Funcionarios!$J$2:$J$176,"<="&$B$10,Funcionarios!$G$2:$G$176,$B$6,Funcionarios!$M$2:$M$176,$C$6)
A16: Desligamentos no ano | B16: =COUNTIFS(Funcionarios!$K$2:$K$176,">="&$B$8,Funcionarios!$K$2:$K$176,"<="&$B$9,Funcionarios!$G$2:$G$176,$B$6,Funcionarios!$M$2:$M$176,$C$6)
A17: Desligamentos mesmo período ano anterior | B17: =COUNTIFS(Funcionarios!$K$2:$K$176,">="&EDATE($B$8,-12),Funcionarios!$K$2:$K$176,"<="&$B$10,Funcionarios!$G$2:$G$176,$B$6,Funcionarios!$M$2:$M$176,$C$6)
A18: Turnover do período | B18: =IFERROR(((B14+B16)/2)/B13,0)
A19: Salário médio (ativos) | B19: =IFERROR(AVERAGEIFS(Funcionarios!$I$2:$I$176,Funcionarios!$O$2:$O$176,"Ativo",Funcionarios!$G$2:$G$176,$B$6,Funcionarios!$M$2:$M$176,$C$6),0)
A20: Folha mensal (ativos) | B20: =SUMIFS(Funcionarios!$I$2:$I$176,Funcionarios!$O$2:$O$176,"Ativo",Funcionarios!$G$2:$G$176,$B$6,Funcionarios!$M$2:$M$176,$C$6)
A21: % mulheres (ativos) | B21: =IFERROR(COUNTIFS(Funcionarios!$O$2:$O$176,"Ativo",Funcionarios!$G$2:$G$176,$B$6,Funcionarios!$M$2:$M$176,$C$6,Funcionarios!$C$2:$C$176,"F")/B13,0)
A22: % mulheres na liderança | B22: =IFERROR(COUNTIFS(Funcionarios!$O$2:$O$176,"Ativo",Funcionarios!$G$2:$G$176,$B$6,Funcionarios!$M$2:$M$176,$C$6,Funcionarios!$C$2:$C$176,"F",Funcionarios!$Q$2:$Q$176,"Sim")/COUNTIFS(Funcionarios!$O$2:$O$176,"Ativo",Funcionarios!$G$2:$G$176,$B$6,Funcionarios!$M$2:$M$176,$C$6,Funcionarios!$Q$2:$Q$176,"Sim"),0)
A23: Tempo médio de casa (anos) | B23: =IFERROR(AVERAGEIFS(Funcionarios!$P$2:$P$176,Funcionarios!$O$2:$O$176,"Ativo",Funcionarios!$G$2:$G$176,$B$6,Funcionarios!$M$2:$M$176,$C$6),0)
A24: Variação admissões | B24: =IF(B15>0,B14/B15-1,"")
A25: Variação desligamentos | B25: =IF(B17>0,B16/B17-1,"")
A27: 3 · HEADCOUNT POR DEPARTAMENTO (ordenado) | C27: filtro de unidade aplicado
A28: Departamento | B28: Ativos | C28: Desempate | E28: Ordem | F28: Depto (ordenado) | G28: Ativos
A29: Comercial | B29: =COUNTIFS(Funcionarios!$O$2:$O$176,"Ativo",Funcionarios!$G$2:$G$176,A29,Funcionarios!$M$2:$M$176,$C$6) | C29: =B29+ROW()/1000000 | E29: 1 | F29: =INDEX($A$29:$A$35,MATCH(LARGE($C$29:$C$35,E29),$C$29:$C$35,0)) | G29: =INDEX($B$29:$B$35,MATCH(LARGE($C$29:$C$35,E29),$C$29:$C$35,0))
A30: Operações | B30: =COUNTIFS(Funcionarios!$O$2:$O$176,"Ativo",Funcionarios!$G$2:$G$176,A30,Funcionarios!$M$2:$M$176,$C$6) | C30: =B30+ROW()/1000000 | E30: 2 | F30: =INDEX($A$29:$A$35,MATCH(LARGE($C$29:$C$35,E30),$C$29:$C$35,0)) | G30: =INDEX($B$29:$B$35,MATCH(LARGE($C$29:$C$35,E30),$C$29:$C$35,0))
A31: Tecnologia | B31: =COUNTIFS(Funcionarios!$O$2:$O$176,"Ativo",Funcionarios!$G$2:$G$176,A31,Funcionarios!$M$2:$M$176,$C$6) | C31: =B31+ROW()/1000000 | E31: 3 | F31: =INDEX($A$29:$A$35,MATCH(LARGE($C$29:$C$35,E31),$C$29:$C$35,0)) | G31: =INDEX($B$29:$B$35,MATCH(LARGE($C$29:$C$35,E31),$C$29:$C$35,0))
A32: Financeiro | B32: =COUNTIFS(Funcionarios!$O$2:$O$176,"Ativo",Funcionarios!$G$2:$G$176,A32,Funcionarios!$M$2:$M$176,$C$6) | C32: =B32+ROW()/1000000 | E32: 4 | F32: =INDEX($A$29:$A$35,MATCH(LARGE($C$29:$C$35,E32),$C$29:$C$35,0)) | G32: =INDEX($B$29:$B$35,MATCH(LARGE($C$29:$C$35,E32),$C$29:$C$35,0))
A33: Marketing | B33: =COUNTIFS(Funcionarios!$O$2:$O$176,"Ativo",Funcionarios!$G$2:$G$176,A33,Funcionarios!$M$2:$M$176,$C$6) | C33: =B33+ROW()/1000000 | E33: 5 | F33: =INDEX($A$29:$A$35,MATCH(LARGE($C$29:$C$35,E33),$C$29:$C$35,0)) | G33: =INDEX($B$29:$B$35,MATCH(LARGE($C$29:$C$35,E33),$C$29:$C$35,0))
A34: RH | B34: =COUNTIFS(Funcionarios!$O$2:$O$176,"Ativo",Funcionarios!$G$2:$G$176,A34,Funcionarios!$M$2:$M$176,$C$6) | C34: =B34+ROW()/1000000 | E34: 6 | F34: =INDEX($A$29:$A$35,MATCH(LARGE($C$29:$C$35,E34),$C$29:$C$35,0)) | G34: =INDEX($B$29:$B$35,MATCH(LARGE($C$29:$C$35,E34),$C$29:$C$35,0))
A35: Diretoria | B35: =COUNTIFS(Funcionarios!$O$2:$O$176,"Ativo",Funcionarios!$G$2:$G$176,A35,Funcionarios!$M$2:$M$176,$C$6) | C35: =B35+ROW()/1000000 | E35: 7 | F35: =INDEX($A$29:$A$35,MATCH(LARGE($C$29:$C$35,E35),$C$29:$C$35,0)) | G35: =INDEX($B$29:$B$35,MATCH(LARGE($C$29:$C$35,E35),$C$29:$C$35,0))
A37: 4 · ADMISSÕES × DESLIGAMENTOS POR MÊS | C37: ano escolhido
A38: Mês | B38: Admissões | C38: Desligamentos
A39: Jan | B39: =COUNTIFS(Funcionarios!$J$2:$J$176,">="&DATE($B$5,1,1),Funcionarios!$J$2:$J$176,"<="&EOMONTH(DATE($B$5,1,1),0),Funcionarios!$G$2:$G$176,$B$6,Funcionarios!$M$2:$M$176,$C$6) | C39: =COUNTIFS(Funcionarios!$K$2:$K$176,">="&DATE($B$5,1,1),Funcionarios!$K$2:$K$176,"<="&EOMONTH(DATE($B$5,1,1),0),Funcionarios!$G$2:$G$176,$B$6,Funcionarios!$M$2:$M$176,$C$6)
A40: Fev | B40: =COUNTIFS(Funcionarios!$J$2:$J$176,">="&DATE($B$5,2,1),Funcionarios!$J$2:$J$176,"<="&EOMONTH(DATE($B$5,2,1),0),Funcionarios!$G$2:$G$176,$B$6,Funcionarios!$M$2:$M$176,$C$6) | C40: =COUNTIFS(Funcionarios!$K$2:$K$176,">="&DATE($B$5,2,1),Funcionarios!$K$2:$K$176,"<="&EOMONTH(DATE($B$5,2,1),0),Funcionarios!$G$2:$G$176,$B$6,Funcionarios!$M$2:$M$176,$C$6)
A41: Mar | B41: =COUNTIFS(Funcionarios!$J$2:$J$176,">="&DATE($B$5,3,1),Funcionarios!$J$2:$J$176,"<="&EOMONTH(DATE($B$5,3,1),0),Funcionarios!$G$2:$G$176,$B$6,Funcionarios!$M$2:$M$176,$C$6) | C41: =COUNTIFS(Funcionarios!$K$2:$K$176,">="&DATE($B$5,3,1),Funcionarios!$K$2:$K$176,"<="&EOMONTH(DATE($B$5,3,1),0),Funcionarios!$G$2:$G$176,$B$6,Funcionarios!$M$2:$M$176,$C$6)
A42: Abr | B42: =COUNTIFS(Funcionarios!$J$2:$J$176,">="&DATE($B$5,4,1),Funcionarios!$J$2:$J$176,"<="&EOMONTH(DATE($B$5,4,1),0),Funcionarios!$G$2:$G$176,$B$6,Funcionarios!$M$2:$M$176,$C$6) | C42: =COUNTIFS(Funcionarios!$K$2:$K$176,">="&DATE($B$5,4,1),Funcionarios!$K$2:$K$176,"<="&EOMONTH(DATE($B$5,4,1),0),Funcionarios!$G$2:$G$176,$B$6,Funcionarios!$M$2:$M$176,$C$6)
A43: Mai | B43: =COUNTIFS(Funcionarios!$J$2:$J$176,">="&DATE($B$5,5,1),Funcionarios!$J$2:$J$176,"<="&EOMONTH(DATE($B$5,5,1),0),Funcionarios!$G$2:$G$176,$B$6,Funcionarios!$M$2:$M$176,$C$6) | C43: =COUNTIFS(Funcionarios!$K$2:$K$176,">="&DATE($B$5,5,1),Funcionarios!$K$2:$K$176,"<="&EOMONTH(DATE($B$5,5,1),0),Funcionarios!$G$2:$G$176,$B$6,Funcionarios!$M$2:$M$176,$C$6)
A44: Jun | B44: =COUNTIFS(Funcionarios!$J$2:$J$176,">="&DATE($B$5,6,1),Funcionarios!$J$2:$J$176,"<="&EOMONTH(DATE($B$5,6,1),0),Funcionarios!$G$2:$G$176,$B$6,Funcionarios!$M$2:$M$176,$C$6) | C44: =COUNTIFS(Funcionarios!$K$2:$K$176,">="&DATE($B$5,6,1),Funcionarios!$K$2:$K$176,"<="&EOMONTH(DATE($B$5,6,1),0),Funcionarios!$G$2:$G$176,$B$6,Funcionarios!$M$2:$M$176,$C$6)
...

Sheet Funcionarios
A1: Matrícula | B1: Nome | C1: Gênero | D1: Nascimento | E1: Idade | F1: Faixa etária | G1: Departamento | H1: Nível | I1: Salário | J1: Admissão | K1: Desligamento | L1: Motivo | M1: Unidade | N1: Avaliação | O1: Status | P1: Tempo de casa (anos) | Q1: Liderança
A2: M1001 | B2: Beatriz Costa | C2: F | D2: 35553 | E2: =DATEDIF(D2,IF(K2="",Calc!$B$7,K2),"y") | F2: =LOOKUP(E2,{0,25,35,45,55},{"18-24","25-34","35-44","45-54","55+"}) | G2: Comercial | H2: Assistente | I2: 2800 | J2: 45034 | M2: Recife | N2: 3.2 | O2: =IF(K2="","Ativo","Desligado") | P2: =ROUND((IF(K2="",Calc!$B$7,K2)-J2)/365.25,1) | Q2: =IF(OR(H2="Coordenação",H2="Gerência",H2="Diretoria"),"Sim","Não")
A3: M1002 | B3: Vinícius Ribeiro | C3: M | D3: 34002 | E3: =DATEDIF(D3,IF(K3="",Calc!$B$7,K3),"y") | F3: =LOOKUP(E3,{0,25,35,45,55},{"18-24","25-34","35-44","45-54","55+"}) | G3: Financeiro | H3: Assistente | I3: 4500 | J3: 43771 | M3: Recife | N3: 3.8 | O3: =IF(K3="","Ativo","Desligado") | P3: =ROUND((IF(K3="",Calc!$B$7,K3)-J3)/365.25,1) | Q3: =IF(OR(H3="Coordenação",H3="Gerência",H3="Diretoria"),"Sim","Não")
A4: M1003 | B4: Henrique Fernandes | C4: M | D4: 35888 | E4: =DATEDIF(D4,IF(K4="",Calc!$B$7,K4),"y") | F4: =LOOKUP(E4,{0,25,35,45,55},{"18-24","25-34","35-44","45-54","55+"}) | G4: Comercial | H4: Assistente | I4: 3500 | J4: 43174 | M4: Recife | N4: 3.7 | O4: =IF(K4="","Ativo","Desligado") | P4: =ROUND((IF(K4="",Calc!$B$7,K4)-J4)/365.25,1) | Q4: =IF(OR(H4="Coordenação",H4="Gerência",H4="Diretoria"),"Sim","Não")
A5: M1004 | B5: Daniela Barbosa | C5: F | D5: 31211 | E5: =DATEDIF(D5,IF(K5="",Calc!$B$7,K5),"y") | F5: =LOOKUP(E5,{0,25,35,45,55},{"18-24","25-34","35-44","45-54","55+"}) | G5: Comercial | H5: Analista | I5: 4150 | J5: 41026 | M5: São Paulo | N5: 4.5 | O5: =IF(K5="","Ativo","Desligado") | P5: =ROUND((IF(K5="",Calc!$B$7,K5)-J5)/365.25,1) | Q5: =IF(OR(H5="Coordenação",H5="Gerência",H5="Diretoria"),"Sim","Não")
A6: M1005 | B6: Mariana Fernandes | C6: F | D6: 25799 | E6: =DATEDIF(D6,IF(K6="",Calc!$B$7,K6),"y") | F6: =LOOKUP(E6,{0,25,35,45,55},{"18-24","25-34","35-44","45-54","55+"}) | G6: Comercial | H6: Assistente | I6: 3600 | J6: 45459 | M6: São Paulo | N6: 2.7 | O6: =IF(K6="","Ativo","Desligado") | P6: =ROUND((IF(K6="",Calc!$B$7,K6)-J6)/365.25,1) | Q6: =IF(OR(H6="Coordenação",H6="Gerência",H6="Diretoria"),"Sim","Não")
A7: M1006 | B7: Carolina Vieira | C7: F | D7: 36857 | E7: =DATEDIF(D7,IF(K7="",Calc!$B$7,K7),"y") | F7: =LOOKUP(E7,{0,25,35,45,55},{"18-24","25-34","35-44","45-54","55+"}) | G7: Tecnologia | H7: Coordenação | I7: 15800 | J7: 44738 | M7: Belo Horizonte | N7: 3.5 | O7: =IF(K7="","Ativo","Desligado") | P7: =ROUND((IF(K7="",Calc!$B$7,K7)-J7)/365.25,1) | Q7: =IF(OR(H7="Coordenação",H7="Gerência",H7="Diretoria"),"Sim","Não")
A8: M1007 | B8: Sofia Rodrigues | C8: F | D8: 29434 | E8: =DATEDIF(D8,IF(K8="",Calc!$B$7,K8),"y") | F8: =LOOKUP(E8,{0,25,35,45,55},{"18-24","25-34","35-44","45-54","55+"}) | G8: Comercial | H8: Assistente | I8: 3350 | J8: 43993 | M8: São Paulo | N8: 3.3 | O8: =IF(K8="","Ativo","Desligado") | P8: =ROUND((IF(K8="",Calc!$B$7,K8)-J8)/365.25,1) | Q8: =IF(OR(H8="Coordenação",H8="Gerência",H8="Diretoria"),"Sim","Não")
A9: M1008 | B9: Eduardo Ribeiro | C9: M | D9: 24848 | E9: =DATEDIF(D9,IF(K9="",Calc!$B$7,K9),"y") | F9: =LOOKUP(E9,{0,25,35,45,55},{"18-24","25-34","35-44","45-54","55+"}) | G9: RH | H9: Especialista | I9: 7050 | J9: 43987 | K9: 45989 | L9: Dispensa | M9: Recife | N9: 2.3 | O9: =IF(K9="","Ativo","Desligado") | P9: =ROUND((IF(K9="",Calc!$B$7,K9)-J9)/365.25,1) | Q9: =IF(OR(H9="Coordenação",H9="Gerência",H9="Diretoria"),"Sim","Não")
A10: M1009 | B10: Marcelo Vieira | C10: M | D10: 37481 | E10: =DATEDIF(D10,IF(K10="",Calc!$B$7,K10),"y") | F10: =LOOKUP(E10,{0,25,35,45,55},{"18-24","25-34","35-44","45-54","55+"}) | G10: Financeiro | H10: Analista | I10: 6350 | J10: 44640 | M10: Curitiba | N10: 3.5 | O10: =IF(K10="","Ativo","Desligado") | P10: =ROUND((IF(K10="",Calc!$B$7,K10)-J10)/365.25,1) | Q10: =IF(OR(H10="Coordenação",H10="Gerência",H10="Diretoria"),"Sim","Não")
A11: M1010 | B11: Beatriz Barbosa | C11: F | D11: 27782 | E11: =DATEDIF(D11,IF(K11="",Calc!$B$7,K11),"y") | F11: =LOOKUP(E11,{0,25,35,45,55},{"18-24","25-34","35-44","45-54","55+"}) | G11: Financeiro | H11: Analista | I11: 6050 | J11: 44174 | K11: 45958 | L11: Pedido de demissão | M11: São Paulo | N11: 3.6 | O11: =IF(K11="","Ativo","Desligado") | P11: =ROUND((IF(K11="",Calc!$B$7,K11)-J11)/365.25,1) | Q11: =IF(OR(H11="Coordenação",H11="Gerência",H11="Diretoria"),"Sim","Não")
A12: M1011 | B12: Thiago Carvalho | C12: M | D12: 35876 | E12: =DATEDIF(D12,IF(K12="",Calc!$B$7,K12),"y") | F12: =LOOKUP(E12,{0,25,35,45,55},{"18-24","25-34","35-44","45-54","55+"}) | G12: Comercial | H12: Assistente | I12: 3250 | J12: 41646 | M12: Recife | N12: 3.9 | O12: =IF(K12="","Ativo","Desligado") | P12: =ROUND((IF(K12="",Calc!$B$7,K12)-J12)/365.25,1) | Q12: =IF(OR(H12="Coordenação",H12="Gerência",H12="Diretoria"),"Sim","Não")
A13: M1012 | B13: Patrícia Ribeiro | C13: F | D13: 34548 | E13: =DATEDIF(D13,IF(K13="",Calc!$B$7,K13),"y") | F13: =LOOKUP(E13,{0,25,35,45,55},{"18-24","25-34","35-44","45-54","55+"}) | G13: Comercial | H13: Assistente | I13: 2800 | J13: 44775 | M13: São Paulo | N13: 3.4 | O13: =IF(K13="","Ativo","Desligado") | P13: =ROUND((IF(K13="",Calc!$B$7,K13)-J13)/365.25,1) | Q13: =IF(OR(H13="Coordenação",H13="Gerência",H13="Diretoria"),"Sim","Não")
A14: M1013 | B14: Leonardo Pereira | C14: M | D14: 28526 | E14: =DATEDIF(D14,IF(K14="",Calc!$B$7,K14),"y") | F14: =LOOKUP(E14,{0,25,35,45,55},{"18-24","25-34","35-44","45-54","55+"}) | G14: Comercial | H14: Gerência | I14: 11250 | J14: 42983 | M14: São Paulo | N14: 4.5 | O14: =IF(K14="","Ativo","Desligado") | P14: =ROUND((IF(K14="",Calc!$B$7,K14)-J14)/365.25,1) | Q14: =IF(OR(H14="Coordenação",H14="Gerência",H14="Diretoria"),"Sim","Não")
A15: M1014 | B15: Thiago Ferreira | C15: M | D15: 27198 | E15: =DATEDIF(D15,IF(K15="",Calc!$B$7,K15),"y") | F15: =LOOKUP(E15,{0,25,35,45,55},{"18-24","25-34","35-44","45-54","55+"}) | G15: Marketing | H15: Assistente | I15: 4400 | J15: 41179 | M15: Recife | N15: 4.1 | O15: =IF(K15="","Ativo","Desligado") | P15: =ROUND((IF(K15="",Calc!$B$7,K15)-J15)/365.25,1) | Q15: =IF(OR(H15="Coordenação",H15="Gerência",H15="Diretoria"),"Sim","Não")
A16: M1015 | B16: Tatiane Nunes | C16: F | D16: 29580 | E16: =DATEDIF(D16,IF(K16="",Calc!$B$7,K16),"y") | F16: =LOOKUP(E16,{0,25,35,45,55},{"18-24","25-34","35-44","45-54","55+"}) | G16: Financeiro | H16: Analista | I16: 5550 | J16: 41382 | M16: Curitiba | N16: 3.9 | O16: =IF(K16="","Ativo","Desligado") | P16: =ROUND((IF(K16="",Calc!$B$7,K16)-J16)/365.25,1) | Q16: =IF(OR(H16="Coordenação",H16="Gerência",H16="Diretoria"),"Sim","Não")
A17: M1016 | B17: Henrique Vieira | C17: M | D17: 30043 | E17: =DATEDIF(D17,IF(K17="",Calc!$B$7,K17),"y") | F17: =LOOKUP(E17,{0,25,35,45,55},{"18-24","25-34","35-44","45-54","55+"}) | G17: Financeiro | H17: Coordenação | I17: 9850 | J17: 41930 | M17: Curitiba | N17: 3 | O17: =IF(K17="","Ativo","Desligado") | P17: =ROUND((IF(K17="",Calc!$B$7,K17)-J17)/365.25,1) | Q17: =IF(OR(H17="Coordenação",H17="Gerência",H17="Diretoria"),"Sim","Não")
A18: M1017 | B18: Camila Martins | C18: F | D18: 29034 | E18: =DATEDIF(D18,IF(K18="",Calc!$B$7,K18),"y") | F18: =LOOKUP(E18,{0,25,35,45,55},{"18-24","25-34","35-44","45-54","55+"}) | G18: Tecnologia | H18: Gerência | I18: 22200 | J18: 44452 | M18: São Paulo | N18: 4 | O18: =IF(K18="","Ativo","Desligado") | P18: =ROUND((IF(K18="",Calc!$B$7,K18)-J18)/365.25,1) | Q18: =IF(OR(H18="Coordenação",H18="Gerência",H18="Diretoria"),"Sim","Não")
A19: M1018 | B19: Leonardo Moreira | C19: M | D19: 37310 | E19: =DATEDIF(D19,IF(K19="",Calc!$B$7,K19),"y") | F19: =LOOKUP(E19,{0,25,35,45,55},{"18-24","25-34","35-44","45-54","55+"}) | G19: Financeiro | H19: Assistente | I19: 4700 | J19: 43252 | M19: Belo Horizonte | N19: 3.7 | O19: =IF(K19="","Ativo","Desligado") | P19: =ROUND((IF(K19="",Calc!$B$7,K19)-J19)/365.25,1) | Q19: =IF(OR(H19="Coordenação",H19="Gerência",H19="Diretoria"),"Sim","Não")
A20: M1019 | B20: Patrícia Vieira | C20: F | D20: 31371 | E20: =DATEDIF(D20,IF(K20="",Calc!$B$7,K20),"y") | F20: =LOOKUP(E20,{0,25,35,45,55},{"18-24","25-34","35-44","45-54","55+"}) | G20: Operações | H20: Analista | I20: 3250 | J20: 41398 | K20: 46199 | L20: Pedido de demissão | M20: São Paulo | N20: 3.1 | O20: =IF(K20="","Ativo","Desligado") | P20: =ROUND((IF(K20="",Calc!$B$7,K20)-J20)/365.25,1) | Q20: =IF(OR(H20="Coordenação",H20="Gerência",H20="Diretoria"),"Sim","Não")
A21: M1020 | B21: Rafael Barbosa | C21: M | D21: 28852 | E21: =DATEDIF(D21,IF(K21="",Calc!$B$7,K21),"y") | F21: =LOOKUP(E21,{0,25,35,45,55},{"18-24","25-34","35-44","45-54","55+"}) | G21: Marketing | H21: Coordenação | I21: 10400 | J21: 43237 | M21: São Paulo | N21: 3.2 | O21: =IF(K21="","Ativo","Desligado") | P21: =ROUND((IF(K21="",Calc!$B$7,K21)-J21)/365.25,1) | Q21: =IF(OR(H21="Coordenação",H21="Gerência",H21="Diretoria"),"Sim","Não")
A22: M1021 | B22: Samuel Vieira | C22: M | D22: 31123 | E22: =DATEDIF(D22,IF(K22="",Calc!$B$7,K22),"y") | F22: =LOOKUP(E22,{0,25,35,45,55},{"18-24","25-34","35-44","45-54","55+"}) | G22: Financeiro | H22: Especialista | I22: 7600 | J22: 41634 | M22: Recife | N22: 3.8 | O22: =IF(K22="","Ativo","Desligado") | P22: =ROUND((IF(K22="",Calc!$B$7,K22)-J22)/365.25,1) | Q22: =IF(OR(H22="Coordenação",H22="Gerência",H22="Diretoria"),"Sim","Não")
A23: M1022 | B23: Igor Gomes | C23: M | D23: 28302 | E23: =DATEDIF(D23,IF(K23="",Calc!$B$7,K23),"y") | F23: =LOOKUP(E23,{0,25,35,45,55},{"18-24","25-34","35-44","45-54","55+"}) | G23: Operações | H23: Analista | I23: 3400 | J23: 45578 | M23: São Paulo | N23: 3.8 | O23: =IF(K23="","Ativo","Desligado") | P23: =ROUND((IF(K23="",Calc!$B$7,K23)-J23)/365.25,1) | Q23: =IF(OR(H23="Coordenação",H23="Gerência",H23="Diretoria"),"Sim","Não")
A24: M1023 | B24: Leonardo Lopes | C24: M | D24: 36261 | E24: =DATEDIF(D24,IF(K24="",Calc!$B$7,K24),"y") | F24: =LOOKUP(E24,{0,25,35,45,55},{"18-24","25-34","35-44","45-54","55+"}) | G24: Tecnologia | H24: Analista | I24: 8250 | J24: 41399 | K24: 45969 | L24: Pedido de demissão | M24: Curitiba | N24: 4.3 | O24: =IF(K24="","Ativo","Desligado") | P24: =ROUND((IF(K24="",Calc!$B$7,K24)-J24)/365.25,1) | Q24: =IF(OR(H24="Coordenação",H24="Gerência",H24="Diretoria"),"Sim","Não")
A25: M1024 | B25: Gabriela Pereira | C25: F | D25: 35009 | E25: =DATEDIF(D25,IF(K25="",Calc!$B$7,K25),"y") | F25: =LOOKUP(E25,{0,25,35,45,55},{"18-24","25-34","35-44","45-54","55+"}) | G25: Tecnologia | H25: Coordenação | I25: 14650 | J25: 45239 | K25: 46111 | L25: Pedido de demissão | M25: São Paulo | N25: 5 | O25: =IF(K25="","Ativo","Desligado") | P25: =ROUND((IF(K25="",Calc!$B$7,K25)-J25)/365.25,1) | Q25: =IF(OR(H25="Coordenação",H25="Gerência",H25="Diretoria"),"Sim","Não")
A26: M1025 | B26: Carlos Oliveira | C26: M | D26: 35017 | E26: =DATEDIF(D26,IF(K26="",Calc!$B$7,K26),"y") | F26: =LOOKUP(E26,{0,25,35,45,55},{"18-24","25-34","35-44","45-54","55+"}) | G26: RH | H26: Especialista | I26: 8000 | J26: 42716 | M26: São Paulo | N26: 3.4 | O26: =IF(K26="","Ativo","Desligado") | P26: =ROUND((IF(K26="",Calc!$B$7,K26)-J26)/365.25,1) | Q26: =IF(OR(H26="Coordenação",H26="Gerência",H26="Diretoria"),"Sim","Não")
A27: M1026 | B27: Felipe Lopes | C27: M | D27: 33073 | E27: =DATEDIF(D27,IF(K27="",Calc!$B$7,K27),"y") | F27: =LOOKUP(E27,{0,25,35,45,55},{"18-24","25-34","35-44","45-54","55+"}) | G27: Financeiro | H27: Especialista | I27: 8200 | J27: 41311 | M27: São Paulo | N27: 3.5 | O27: =IF(K27="","Ativo","Desligado") | P27: =ROUND((IF(K27="",Calc!$B$7,K27)-J27)/365.25,1) | Q27: =IF(OR(H27="Coordenação",H27="Gerência",H27="Diretoria"),"Sim","Não")
A28: M1027 | B28: Natália Alves | C28: F | D28: 29544 | E28: =DATEDIF(D28,IF(K28="",Calc!$B$7,K28),"y") | F28: =LOOKUP(E28,{0,25,35,45,55},{"18-24","25-34","35-44","45-54","55+"}) | G28: Tecnologia | H28: Assistente | I28: 6600 | J28: 45503 | M28: São Paulo | N28: 4.6 | O28: =IF(K28="","Ativo","Desligado") | P28: =ROUND((IF(K28="",Calc!$B$7,K28)-J28)/365.25,1) | Q28: =IF(OR(H28="Coordenação",H28="Gerência",H28="Diretoria"),"Sim","Não")
A29: M1028 | B29: Bruno Almeida | C29: M | D29: 35659 | E29: =DATEDIF(D29,IF(K29="",Calc!$B$7,K29),"y") | F29: =LOOKUP(E29,{0,25,35,45,55},{"18-24","25-34","35-44","45-54","55+"}) | G29: Comercial | H29: Assistente | I29: 3050 | J29: 45262 | K29: 45658 | L29: Dispensa | M29: Curitiba | N29: 4.4 | O29: =IF(K29="","Ativo","Desligado") | P29: =ROUND((IF(K29="",Calc!$B$7,K29)-J29)/365.25,1) | Q29: =IF(OR(H29="Coordenação",H29="Gerência",H29="Diretoria"),"Sim","Não")
A30: M1029 | B30: Larissa Pereira | C30: F | D30: 34044 | E30: =DATEDIF(D30,IF(K30="",Calc!$B$7,K30),"y") | F30: =LOOKUP(E30,{0,25,35,45,55},{"18-24","25-34","35-44","45-54","55+"}) | G30: Operações | H30: Analista | I30: 3300 | J30: 42435 | M30: Belo Horizonte | N30: 5 | O30: =IF(K30="","Ativo","Desligado") | P30: =ROUND((IF(K30="",Calc!$B$7,K30)-J30)/365.25,1) | Q30: =IF(OR(H30="Coordenação",H30="Gerência",H30="Diretoria"),"Sim","Não")
A31: M1030 | B31: Henrique Silva | C31: M | D31: 30970 | E31: =DATEDIF(D31,IF(K31="",Calc!$B$7,K31),"y") | F31: =LOOKUP(E31,{0,25,35,45,55},{"18-24","25-34","35-44","45-54","55+"}) | G31: Operações | H31: Assistente | I31: 2250 | J31: 42962 | K31: 46246 | L31: Pedido de demissão | M31: São Paulo | N31: 4.3 | O31: =IF(K31="","Ativo","Desligado") | P31: =ROUND((IF(K31="",Calc!$B$7,K31)-J31)/365.25,1) | Q31: =IF(OR(H31="Coordenação",H31="Gerência",H31="Diretoria"),"Sim","Não")
A32: M1031 | B32: Gabriela Moreira | C32: F | D32: 30019 | E32: =DATEDIF(D32,IF(K32="",Calc!$B$7,K32),"y") | F32: =LOOKUP(E32,{0,25,35,45,55},{"18-24","25-34","35-44","45-54","55+"}) | G32: Operações | H32: Assistente | I32: 2550 | J32: 41239 | M32: São Paulo | N32: 3.4 | O32: =IF(K32="","Ativo","Desligado") | P32: =ROUND((IF(K32="",Calc!$B$7,K32)-J32)/365.25,1) | Q32: =IF(OR(H32="Coordenação",H32="Gerência",H32="Diretoria"),"Sim","Não")
A33: M1032 | B33: Patrícia Nunes | C33: F | D33: 27293 | E33: =DATEDIF(D33,IF(K33="",Calc!$B$7,K33),"y") | F33: =LOOKUP(E33,{0,25,35,45,55},{"18-24","25-34","35-44","45-54","55+"}) | G33: Marketing | H33: Assistente | I33: 4000 | J33: 45590 | M33: São Paulo | N33: 3.9 | O33: =IF(K33="","Ativo","Desligado") | P33: =ROUND((IF(K33="",Calc!$B$7,K33)-J33)/365.25,1) | Q33: =IF(OR(H33="Coordenação",H33="Gerência",H33="Diretoria"),"Sim","Não")
A34: M1033 | B34: João Souza | C34: M | D34: 24209 | E34: =DATEDIF(D34,IF(K34="",Calc!$B$7,K34),"y") | F34: =LOOKUP(E34,{0,25,35,45,55},{"18-24","25-34","35-44","45-54","55+"}) | G34: Financeiro | H34: Analista | I34: 5300 | J34: 42387 | M34: Curitiba | N34: 3.3 | O34: =IF(K34="","Ativo","Desligado") | P34: =ROUND((IF(K34="",Calc!$B$7,K34)-J34)/365.25,1) | Q34: =IF(OR(H34="Coordenação",H34="Gerência",H34="Diretoria"),"Sim","Não")
A35: M1034 | B35: Felipe Nunes | C35: M | D35: 28267 | E35: =DATEDIF(D35,IF(K35="",Calc!$B$7,K35),"y") | F35: =LOOKUP(E35,{0,25,35,45,55},{"18-24","25-34","35-44","45-54","55+"}) | G35: Operações | H35: Analista | I35: 3400 | J35: 41511 | K35: 45677 | L35: Dispensa | M35: Recife | N35: 3.2 | O35: =IF(K35="","Ativo","Desligado") | P35: =ROUND((IF(K35="",Calc!$B$7,K35)-J35)/365.25,1) | Q35: =IF(OR(H35="Coordenação",H35="Gerência",H35="Diretoria"),"Sim","Não")
A36: M1035 | B36: Gabriela Nunes | C36: F | D36: 37327 | E36: =DATEDIF(D36,IF(K36="",Calc!$B$7,K36),"y") | F36: =LOOKUP(E36,{0,25,35,45,55},{"18-24","25-34","35-44","45-54","55+"}) | G36: Operações | H36: Analista | I36: 3550 | J36: 43832 | M36: Curitiba | N36: 4 | O36: =IF(K36="","Ativo","Desligado") | P36: =ROUND((IF(K36="",Calc!$B$7,K36)-J36)/365.25,1) | Q36: =IF(OR(H36="Coordenação",H36="Gerência",H36="Diretoria"),"Sim","Não")
A37: M1036 | B37: Fernanda Nunes | C37: F | D37: 35727 | E37: =DATEDIF(D37,IF(K37="",Calc!$B$7,K37),"y") | F37: =LOOKUP(E37,{0,25,35,45,55},{"18-24","25-34","35-44","45-54","55+"}) | G37: Comercial | H37: Analista | I37: 4450 | J37: 41619 | M37: São Paulo | N37: 3.7 | O37: =IF(K37="","Ativo","Desligado") | P37: =ROUND((IF(K37="",Calc!$B$7,K37)-J37)/365.25,1) | Q37: =IF(OR(H37="Coordenação",H37="Gerência",H37="Diretoria"),"Sim","Não")
A38: M1037 | B38: Mariana Rodrigues | C38: F | D38: 32260 | E38: =DATEDIF(D38,IF(K38="",Calc!$B$7,K38),"y") | F38: =LOOKUP(E38,{0,25,35,45,55},{"18-24","25-34","35-44","45-54","55+"}) | G38: Comercial | H38: Analista | I38: 4650 | J38: 42805 | M38: Curitiba | N38: 4.2 | O38: =IF(K38="","Ativo","Desligado") | P38: =ROUND((IF(K38="",Calc!$B$7,K38)-J38)/365.25,1) | Q38: =IF(OR(H38="Coordenação",H38="Gerência",H38="Diretoria"),"Sim","Não")
A39: M1038 | B39: Gabriela Almeida | C39: F | D39: 27933 | E39: =DATEDIF(D39,IF(K39="",Calc!$B$7,K39),"y") | F39: =LOOKUP(E39,{0,25,35,45,55},{"18-24","25-34","35-44","45-54","55+"}) | G39: Comercial | H39: Analista | I39: 4050 | J39: 42386 | M39: São Paulo | N39: 3.2 | O39: =IF(K39="","Ativo","Desligado") | P39: =ROUND((IF(K39="",Calc!$B$7,K39)-J39)/365.25,1) | Q39: =IF(OR(H39="Coordenação",H39="Gerência",H39="Diretoria"),"Sim","Não")
A40: M1039 | B40: Leonardo Costa | C40: M | D40: 32621 | E40: =DATEDIF(D40,IF(K40="",Calc!$B$7,K40),"y") | F40: =LOOKUP(E40,{0,25,35,45,55},{"18-24","25-34","35-44","45-54","55+"}) | G40: Marketing | H40: Assistente | I40: 4250 | J40: 41463 | M40: Curitiba | N40: 3.7 | O40: =IF(K40="","Ativo","Desligado") | P40: =ROUND((IF(K40="",Calc!$B$7,K40)-J40)/365.25,1) | Q40: =IF(OR(H40="Coordenação",H40="Gerência",H40="Diretoria"),"Sim","Não")
...
